Workbook

Sheet Rekapitulace stavby
A1: Export Komplet | BA1: 2.0 | BB1: ZAMOK | BT1: False | BU1: False | BV1: {a78f166c-8b6e-4fa3-8fd5-52050218beff}
BS2: 0,01 | BT2: 21
BS3: 0,01 | BT3: 12
D4: REKAPITULACE STAVBY | AS4: v --- níže se nacházejí doplnkové a pomocné údaje k sestavám --- v | BE4: Návod na vyplnění | BS4: 0,001
D5: Kód: | K5: CB_II/634-001 | BE5: Měnit lze pouze buňky se žlutým podbarvením!_x000D_ _x000D_ 1) na prvním listu Rekapitulace stavby vyplňte v sestavě_x000D_ _x000D_ a) Souhrnný list_x000D_ - údaje o Uchazeči_x000D_ (přenesou se do ostatních sestav i v jiných listech)_x000D_ _x000D_ b) Rekapitulace objektů_x000D_ - potřebné Ostatní náklady_x000D_ _x000D_ 2) na vybraných listech vyplňte v sestavě_x000D_ _x000D_ a) Krycí list_x000D_ - údaje o Uchazeči, pokud se liší od údajů o Uchazeči na Souhrnném listu_x000D_ (údaje se přenesou do ostatních sestav v daném listu)_x000D_ _x000D_ b) Rekapitulace rozpočtu_x000D_ - potřebné Ostatní náklady_x000D_ _x000D_ c) Celkové náklady za stavbu_x000D_ - ceny u položek_x000D_ - množství, pokud má žluté podbarvení_x000D_ - a v případě potřeby poznámku (ta je ve skrytém sloupci) | BS5: 0,01
D6: Stavba: | K6: Oprava silnice II/634 Rudolfov-Klauda | BS6: 0,01
D7: KSO: | AK7: CC-CZ: | BS7: 0,01
D8: Místo: | K8: Rudolfov-Klauda | AK8: Datum: | AN8: Vyplň údaj | BS8: 0,01
BS9: 0,01
D10: Zadavatel: | AK10: IČ: | AN10: 70890650 | BS10: 0,01
E11: Jihočeský kraj | AK11: DIČ: | AN11: CZ70890650 | BS11: 0,01
BS12: 0,01
D13: Uchazeč: | AK13: IČ: | AN13: Vyplň údaj | BS13: 0,01
E14: Vyplň údaj | AK14: DIČ: | AN14: Vyplň údaj | BS14: 0,01
BS15: False
D16: Projektant: | AK16: IČ: | AN16: 70971641 | BS16: False
E17: Správa a údržba silnic Jihočeského kraje p.o. | AK17: DIČ: | AN17: CZ70971641 | BS17: True
BS18: 0,01
D19: Zpracovatel: | AK19: IČ: | BS19: 0,01
E20: Petr Nachtigal 606 633 836 | AK20: DIČ: | BS20: True
D22: Poznámka:
E23: Délka realizace: 25 kalendářních dnů
D26: Cena bez DPH | AK26: =ROUND(AG94,2) -> 0
L28: Sazba daně | W28: Základ daně | AK28: Výše daně
D29: DPH | F29: základní | L29: 0.21 | W29: =ROUND(AZ94, 2) -> 0 | AK29: =ROUND(AV94, 2) -> 0
F30: snížená | L30: 0.12 | W30: =ROUND(BA94, 2) -> 0 | AK30: =ROUND(AW94, 2) -> 0
F31: zákl. přenesená | L31: 0.21 | W31: =ROUND(BB94, 2) -> 0 | AK31: 0
F32: sníž. přenesená | L32: 0.12 | W32: =ROUND(BC94, 2) -> 0 | AK32: 0
F33: nulová | L33: 0 | W33: =ROUND(BD94, 2) -> 0 | AK33: 0
D35: Cena s DPH | T35: v | X35: CZK | AK35: =SUM(AK26:AK33) -> 0
D49: Projektant | AH49: Zpracovatel
D60: Datum a podpis: | V60: Razítko | AH60: Datum a podpis: | AM60: Razítko
D64: Objednavatel | AH64: Uchazeč
D75: Datum a podpis: | V75: Razítko | AH75: Datum a podpis: | AM75: Razítko
C82: REKAPITULACE OBJEKTŮ STAVBY A SOUPISŮ PRACÍ
C84: Kód: | L84: =K5 -> CB_II/634-001
C85: Stavba: | L85: =K6 -> Oprava silnice II/634 Rudolfov-Klauda
C87: Místo: | L87: =IF(K8="","",K8) -> Rudolfov-Klauda | AI87: Datum: | AM87: =IF(AN8= "","",AN8) -> Vyplň údaj
C89: Zadavatel: | L89: =IF(E11= "","",E11) -> Jihočeský kraj | AI89: Projektant: | AM89: =IF(E17="","",E17) -> Správa a údržba silnic Jihočeského kraje p.o. | AS89: Informatívní údaje z listů zakázek
C90: Uchazeč: | L90: =IF(E14= "Vyplň údaj","",E14) | AI90: Zpracovatel: | AM90: =IF(E20="","",E20) -> Petr Nachtigal 606 633 836
...

Sheet SO101 - Oprava silniceII-...
AT2: {9cc8bc20-5045-440f-bc7d-6e37ef741e5d}
AT3: 2
D4: KRYCÍ LIST SOUPISU PRACÍ | M4: v --- níže se nacházejí doplnkové a pomocné údaje k sestavám --- v | AT4: False
D6: Stavba:
E7: ='Rekapitulace stavby'!K6 -> Oprava silnice II/634 Rudolfov-Klauda
D8: Objekt:
E9: SO101 - Oprava silniceII/634 Rudolfov-Klauda, staničení km 5,278-6,700
D11: KSO: | I11: CC-CZ:
D12: Místo: | F12: Rudolfov-Klauda | I12: Datum: | J12: ='Rekapitulace stavby'!AN8 -> Vyplň údaj
D14: Zadavatel: | I14: IČ: | J14: 70890650
E15: Jihočeský kraj | I15: DIČ: | J15: CZ70890650
D17: Uchazeč: | I17: IČ: | J17: ='Rekapitulace stavby'!AN13 -> Vyplň údaj
E18: ='Rekapitulace stavby'!E14 -> Vyplň údaj | I18: DIČ: | J18: ='Rekapitulace stavby'!AN14 -> Vyplň údaj
D20: Projektant: | I20: IČ: | J20: 70971641
E21: Správa a údržba silnic Jihočeského kraje p.o. | I21: DIČ: | J21: CZ70971641
D23: Zpracovatel: | I23: IČ:
E24: Petr Nachtigal 606 633 836 | I24: DIČ:
D26: Poznámka:
D30: Cena bez DPH | J30: =ROUND(J122, 2) -> 0
F32: Základ daně | I32: Sazba daně | J32: Výše daně
D33: DPH | E33: základní | F33: =ROUND((SUM(BE122:BE329)), 2) -> 0 | I33: 0.21 | J33: =ROUND(((SUM(BE122:BE329))*I33), 2) -> 0
E34: snížená | F34: =ROUND((SUM(BF122:BF329)), 2) -> 0 | I34: 0.12 | J34: =ROUND(((SUM(BF122:BF329))*I34), 2) -> 0
E35: zákl. přenesená | F35: =ROUND((SUM(BG122:BG329)), 2) -> 0 | I35: 0.21 | J35: =0 -> 0
E36: sníž. přenesená | F36: =ROUND((SUM(BH122:BH329)), 2) -> 0 | I36: 0.12 | J36: =0 -> 0
E37: nulová | F37: =ROUND((SUM(BI122:BI329)), 2) -> 0 | I37: 0 | J37: =0 -> 0
D39: Cena s DPH | G39: v | H39: CZK | J39: =SUM(J30:J37) -> 0
D50: Projektant | G50: Zpracovatel
D61: Datum a podpis: | F61: Razítko | G61: Datum a podpis: | J61: Razítko
D65: Objednavatel | G65: Uchazeč
D76: Datum a podpis: | F76: Razítko | G76: Datum a podpis: | J76: Razítko
C82: REKAPITULACE ČLENĚNÍ SOUPISU PRACÍ
C84: Stavba:
E85: =E7 -> Oprava silnice II/634 Rudolfov-Klauda
C86: Objekt:
E87: =E9 -> SO101 - Oprava silniceII/634 Rudolfov-Klauda, staničení km 5,278-6,700
C89: Místo: | F89: =F12 -> Rudolfov-Klauda | I89: Datum: | J89: =IF(J12="","",J12) -> Vyplň údaj
C91: Zadavatel: | F91: =E15 -> Jihočeský kraj | I91: Projektant: | J91: =E21 -> Správa a údržba silnic Jihočeského kraje p.o.
C92: Uchazeč: | F92: =IF(E18="","",E18) -> Vyplň údaj | I92: Zpracovatel: | J92: =E24 -> Petr Nachtigal 606 633 836
C94: Kód dílu - Popis | J94: Cena celkem [CZK]
C96: Náklady ze soupisu prací | J96: =J122 -> 0 | AU96: -1
...

Sheet SO102 - DIO
AT2: {1f558fdb-73fd-4fab-bf58-10a340866e8f}
AT3: 2
D4: KRYCÍ LIST SOUPISU PRACÍ | M4: v --- níže se nacházejí doplnkové a pomocné údaje k sestavám --- v | AT4: False
D6: Stavba:
E7: ='Rekapitulace stavby'!K6 -> Oprava silnice II/634 Rudolfov-Klauda
D8: Objekt:
E9: SO102 - DIO
D11: KSO: | I11: CC-CZ:
D12: Místo: | F12: Rudolfov-Klauda | I12: Datum: | J12: ='Rekapitulace stavby'!AN8 -> Vyplň údaj
D14: Zadavatel: | I14: IČ: | J14: 70890650
E15: Jihočeský kraj | I15: DIČ: | J15: CZ70890650
D17: Uchazeč: | I17: IČ: | J17: ='Rekapitulace stavby'!AN13 -> Vyplň údaj
E18: ='Rekapitulace stavby'!E14 -> Vyplň údaj | I18: DIČ: | J18: ='Rekapitulace stavby'!AN14 -> Vyplň údaj
D20: Projektant: | I20: IČ: | J20: 70971641
E21: Správa a údržba silnic Jihočeského kraje p.o. | I21: DIČ: | J21: CZ70971641
D23: Zpracovatel: | I23: IČ:
E24: Petr Nachtigal 606 633 836 | I24: DIČ:
D26: Poznámka:
D30: Cena bez DPH | J30: =ROUND(J119, 2) -> 0
F32: Základ daně | I32: Sazba daně | J32: Výše daně
D33: DPH | E33: základní | F33: =ROUND((SUM(BE119:BE227)), 2) -> 0 | I33: 0.21 | J33: =ROUND(((SUM(BE119:BE227))*I33), 2) -> 0
E34: snížená | F34: =ROUND((SUM(BF119:BF227)), 2) -> 0 | I34: 0.12 | J34: =ROUND(((SUM(BF119:BF227))*I34), 2) -> 0
E35: zákl. přenesená | F35: =ROUND((SUM(BG119:BG227)), 2) -> 0 | I35: 0.21 | J35: =0 -> 0
E36: sníž. přenesená | F36: =ROUND((SUM(BH119:BH227)), 2) -> 0 | I36: 0.12 | J36: =0 -> 0
E37: nulová | F37: =ROUND((SUM(BI119:BI227)), 2) -> 0 | I37: 0 | J37: =0 -> 0
D39: Cena s DPH | G39: v | H39: CZK | J39: =SUM(J30:J37) -> 0
D50: Projektant | G50: Zpracovatel
D61: Datum a podpis: | F61: Razítko | G61: Datum a podpis: | J61: Razítko
D65: Objednavatel | G65: Uchazeč
D76: Datum a podpis: | F76: Razítko | G76: Datum a podpis: | J76: Razítko
C82: REKAPITULACE ČLENĚNÍ SOUPISU PRACÍ
C84: Stavba:
E85: =E7 -> Oprava silnice II/634 Rudolfov-Klauda
C86: Objekt:
E87: =E9 -> SO102 - DIO
C89: Místo: | F89: =F12 -> Rudolfov-Klauda | I89: Datum: | J89: =IF(J12="","",J12) -> Vyplň údaj
C91: Zadavatel: | F91: =E15 -> Jihočeský kraj | I91: Projektant: | J91: =E21 -> Správa a údržba silnic Jihočeského kraje p.o.
C92: Uchazeč: | F92: =IF(E18="","",E18) -> Vyplň údaj | I92: Zpracovatel: | J92: =E24 -> Petr Nachtigal 606 633 836
C94: Kód dílu - Popis | J94: Cena celkem [CZK]
C96: Náklady ze soupisu prací | J96: =J119 -> 0 | AU96: -1
...

Sheet SO103 - Doplňující údaje 
AT2: {071c7aec-1539-460d-b9ed-ffb9347be52a}
AT3: 2
D4: KRYCÍ LIST SOUPISU PRACÍ | M4: v --- níže se nacházejí doplnkové a pomocné údaje k sestavám --- v | AT4: False
D6: Stavba:
E7: ='Rekapitulace stavby'!K6 -> Oprava silnice II/634 Rudolfov-Klauda
D8: Objekt:
E9: SO103 - Doplňující údaje
D11: KSO: | I11: CC-CZ:
D12: Místo: | F12: Rudolfov-Klauda | I12: Datum: | J12: ='Rekapitulace stavby'!AN8 -> Vyplň údaj
D14: Zadavatel: | I14: IČ: | J14: 70890650
E15: Jihočeský kraj | I15: DIČ: | J15: CZ70890650
D17: Uchazeč: | I17: IČ: | J17: ='Rekapitulace stavby'!AN13 -> Vyplň údaj
E18: ='Rekapitulace stavby'!E14 -> Vyplň údaj | I18: DIČ: | J18: ='Rekapitulace stavby'!AN14 -> Vyplň údaj
D20: Projektant: | I20: IČ: | J20: 70971641
E21: Správa a údržba silnic Jihočeského kraje p.o. | I21: DIČ: | J21: CZ70971641
D23: Zpracovatel: | I23: IČ:
E24: Petr Nachtigal 606 633 836 | I24: DIČ:
D26: Poznámka:
D30: Cena bez DPH | J30: =ROUND(J117, 2) -> 0
F32: Základ daně | I32: Sazba daně | J32: Výše daně
D33: DPH | E33: základní | F33: =ROUND((SUM(BE117:BE130)), 2) -> 0 | I33: 0.21 | J33: =ROUND(((SUM(BE117:BE130))*I33), 2) -> 0
E34: snížená | F34: =ROUND((SUM(BF117:BF130)), 2) -> 0 | I34: 0.12 | J34: =ROUND(((SUM(BF117:BF130))*I34), 2) -> 0
E35: zákl. přenesená | F35: =ROUND((SUM(BG117:BG130)), 2) -> 0 | I35: 0.21 | J35: =0 -> 0
E36: sníž. přenesená | F36: =ROUND((SUM(BH117:BH130)), 2) -> 0 | I36: 0.12 | J36: =0 -> 0
E37: nulová | F37: =ROUND((SUM(BI117:BI130)), 2) -> 0 | I37: 0 | J37: =0 -> 0
D39: Cena s DPH | G39: v | H39: CZK | J39: =SUM(J30:J37) -> 0
D50: Projektant | G50: Zpracovatel
D61: Datum a podpis: | F61: Razítko | G61: Datum a podpis: | J61: Razítko
D65: Objednavatel | G65: Uchazeč
D76: Datum a podpis: | F76: Razítko | G76: Datum a podpis: | J76: Razítko
C82: REKAPITULACE ČLENĚNÍ SOUPISU PRACÍ
C84: Stavba:
E85: =E7 -> Oprava silnice II/634 Rudolfov-Klauda
C86: Objekt:
E87: =E9 -> SO103 - Doplňující údaje
C89: Místo: | F89: =F12 -> Rudolfov-Klauda | I89: Datum: | J89: =IF(J12="","",J12) -> Vyplň údaj
C91: Zadavatel: | F91: =E15 -> Jihočeský kraj | I91: Projektant: | J91: =E21 -> Správa a údržba silnic Jihočeského kraje p.o.
C92: Uchazeč: | F92: =IF(E18="","",E18) -> Vyplň údaj | I92: Zpracovatel: | J92: =E24 -> Petr Nachtigal 606 633 836
C94: Kód dílu - Popis | J94: Cena celkem [CZK]
C96: Náklady ze soupisu prací | J96: =J117 -> 0 | AU96: -1
...
